Workbook

Sheet P&L Gerencial
A1: PERU ON ICE S.A.C. — P&L GERENCIAL 2025 (SIN IGV)
A2: RUC: 20613509446 | Moneda: S/ Soles | Sin IGV | Ejercicio: Enero–Diciembre 2025
A4: CONCEPTO | B4: CTA. | C4: ENE | D4: FEB | E4: MAR | F4: ABR | G4: MAY | H4: JUN | I4: JUL | J4: AGO | K4: SET | L4: OCT | M4: NOV | N4: DIC | O4: TOTAL ANUAL | P4: % REV.
A5: A. INGRESOS
A6: Ingresos por Servicios de Pista | B6: 7032100 | C6: 192370.04 | D6: 214297.38 | E6: 159044.24 | F6: 162394.91 | G6: 146655.75 | H6: 148722.4 | I6: 185458.76 | J6: 177730.07 | K6: 139427.16 | L6: 144036.01 | M6: 140103.32 | N6: 192603.92 | O6: =SUM(C6:N6) -> 2002844 | P6: =IFERROR(O6/O6,0) -> 1
A7: ► Ticket Promedio
A8: TOTAL INGRESOS | C8: =C6 -> 192370.04 | D8: =D6 -> 214297.38 | E8: =E6 -> 159044.24 | F8: =F6 -> 162394.91 | G8: =G6 -> 146655.75 | H8: =H6 -> 148722.4 | I8: =I6 -> 185458.76 | J8: =J6 -> 177730.07 | ... N8: =N6 -> 192603.92 | O8: =SUM(C8:N8) -> 2002844 | P8: =IFERROR(O8/O6,0) -> 1
A10: B. COSTOS OPERATIVOS DEL HIELO
A11: Energía Eléctrica | B11: 6361100 | C11: 22754.51 | D11: 24839.76 | E11: 23204.47 | F11: 22781.98 | G11: 20410.69 | H11: 18773.92 | I11: 17726.41 | J11: 17115.76 | K11: 17788.04 | L11: 16850.1 | M11: 17318.98 | N11: 18987.72 | O11: =SUM(C11:N11) -> 238552.34 | P11: =IFERROR(O11/O6,0) -> 0.1191068
A12: Alquiler Chiller (Refrigeración) | B12: 6352101 | C12: 19000 | D12: 19000 | E12: 0 | F12: 19000 | G12: 19000 | H12: 19000 | I12: 19000 | J12: 19000 | K12: 19000 | L12: 19000 | M12: 19000 | N12: 19000 | O12: =SUM(C12:N12) -> 209000 | P12: =IFERROR(O12/O6,0) -> 0.10435161
A13: Agua | B13: 6363100 | C13: 1097.03 | D13: 1043.05 | E13: 837.89 | F13: 676.25 | G13: 783.81 | H13: 621.87 | I13: 438.81 | J13: 524.66 | K13: 582.14 | L13: 473.18 | M13: 624.77 | N13: 470.98 | O13: =SUM(C13:N13) -> 8174.44 | P13: =IFERROR(O13/O6,0) -> 0.0040814163
A14: Mantenimiento Local | B14: 6341101 | C14: 100 | D14: 0 | E14: 135.59 | F14: 1800 | G14: 950 | H14: 350 | I14: 596.95 | J14: 930 | K14: 14665.22 | L14: 700 | M14: 2076.02 | N14: 0 | O14: =SUM(C14:N14) -> 22303.78 | P14: =IFERROR(O14/O6,0) -> 0.011136055
A15: Mant. Prop. Planta y Equipo | B15: 6343100 | C15: 250 | D15: 0 | E15: 0 | F15: 0 | G15: 0 | H15: 0 | I15: 1000 | J15: 0 | K15: 2450 | L15: 0 | M15: 0 | N15: 0 | O15: =SUM(C15:N15) -> 3700 | P15: =IFERROR(O15/O6,0) -> 0.0018473731
A16: Servicio de Patinaje | B16: 6381115 | C16: 500 | D16: 0 | E16: 0 | F16: 0 | G16: 0 | H16: 0 | I16: 360 | J16: 600 | K16: 0 | L16: 0 | M16: 0 | N16: 0 | O16: =SUM(C16:N16) -> 1460 | P16: =IFERROR(O16/O6,0) -> 0.00072896343
A17: Servicio Tópico (Enfermería) | B17: 6381117 | C17: 560 | D17: 240 | E17: 640 | F17: 1381.44 | G17: 620 | H17: 0 | I17: 1569.92 | J17: 500 | K17: 291.95 | L17: 340 | M17: 1107.63 | N17: 300 | O17: =SUM(C17:N17) -> 7550.94 | P17: =IFERROR(O17/O6,0) -> 0.003770109
A18: Suministros Operativos | B18: 6561100 | C18: 2449.14 | D18: 135.59 | E18: 2237.28 | F18: 0 | G18: 0 | H18: 720.34 | I18: 0 | J18: 369.49 | K18: 0 | L18: 779.65 | M18: 0 | N18: 1864.39 | O18: =SUM(C18:N18) -> 8555.88 | P18: =IFERROR(O18/O6,0) -> 0.0042718655
A19: Útiles de Aseo | B19: 6561103 | C19: 0 | D19: 5.08 | E19: 1255.09 | F19: 1186.44 | G19: 0 | H19: 1016.1 | I19: 919.41 | J19: 933.05 | K19: 392.37 | L19: 722.03 | M19: 922.89 | N19: 0 | O19: =SUM(C19:N19) -> 7352.46 | P19: =IFERROR(O19/O6,0) -> 0.0036710099
A20: Artículos de Ferretería | B20: 6561104 | C20: 409.16 | D20: 110.08 | E20: 718.21 | F20: 244.5 | G20: 144.06 | H20: 10.17 | I20: 382.29 | J20: 630.51 | K20: 158.06 | L20: 25.42 | M20: 985.15 | N20: 33.9 | O20: =SUM(C20:N20) -> 3851.51 | P20: =IFERROR(O20/O6,0) -> 0.0019230205
A21: Botiquín | B21: 6561106 | C21: 61.86 | D21: 212.12 | E21: 0 | F21: 0 | G21: 14.49 | H21: 31.02 | I21: 59.91 | J21: 19.57 | K21: 25.42 | L21: 0 | M21: 0 | N21: 304.66 | O21: =SUM(C21:N21) -> 729.05 | P21: =IFERROR(O21/O6,0) -> 0.00036400739
A22: Gastos a Reparar | B22: 6591104 | C22: 1213 | D22: 22 | E22: 0 | F22: 78.36 | G22: 402 | H22: 200 | I22: 24 | J22: 0 | K22: 1728.1 | L22: 0 | M22: 0 | N22: 0 | O22: =SUM(C22:N22) -> 3667.46 | P22: =IFERROR(O22/O6,0) -> 0.0018311262
A23: Uniformes | B23: 6591105 | C23: 130 | D23: 0 | E23: 172.88 | F23: 72 | G23: 49.66 | H23: 0 | I23: 130.51 | J23: 0 | K23: 0 | L23: 0 | M23: 0 | N23: 0 | O23: =SUM(C23:N23) -> 555.05 | P23: =IFERROR(O23/O6,0) -> 0.00027713093
A24: TOTAL COSTOS OPERATIVOS DEL HIELO | C24: =C11+C12+C13+C14+C15+C16+C17+C18+C19+C20+C21+C22+C23 -> 48524.7 | D24: =D11+D12+D13+D14+D15+D16+D17+D18+D19+D20+D21+D22+D23 -> 45607.68 | E24: =E11+E12+E13+E14+E15+E16+E17+E18+E19+E20+E21+E22+E23 -> 29201.41 | F24: =F11+F12+F13+F14+F15+F16+F17+F18+F19+F20+F21+F22+F23 -> 47220.97 | G24: =G11+G12+G13+G14+G15+G16+G17+G18+G19+G20+G21+G22+G23 -> 42374.71 | H24: =H11+H12+H13+H14+H15+H16+H17+H18+H19+H20+H21+H22+H23 -> 40723.42 | I24: =I11+I12+I13+I14+I15+I16+I17+I18+I19+I20+I21+I22+I23 -> 42208.21 | J24: =J11+J12+J13+J14+J15+J16+J17+J18+J19+J20+J21+J22+J23 -> 40623.04 | ... N24: =N11+N12+N13+N14+N15+N16+N17+N18+N19+N20+N21+N22+N23 -> 40961.65 | O24: =SUM(C24:N24) -> 515452.91 | P24: =IFERROR(O24/O6,0) -> 0.25736049
A25: ★ UTILIDAD BRUTA OPERATIVA (A − B) | C25: =C8-C24 -> 143845.34 | D25: =D8-D24 -> 168689.7 | E25: =E8-E24 -> 129842.83 | F25: =F8-F24 -> 115173.94 | G25: =G8-G24 -> 104281.04 | H25: =H8-H24 -> 107998.98 | I25: =I8-I24 -> 143250.55 | J25: =J8-J24 -> 137107.03 | ... N25: =N8-N24 -> 151642.27 | O25: =SUM(C25:N25) -> 1487391.1 | P25: =IFERROR(O25/O6,0) -> 0.74263951
A26: Margen Bruto Operativo (%) | C26: =IFERROR(C25/C6,0) -> 0.74775334 | D26: =IFERROR(D25/D6,0) -> 0.78717575 | E26: =IFERROR(E25/E6,0) -> 0.81639442 | F26: =IFERROR(F25/F6,0) -> 0.70922137 | G26: =IFERROR(G25/G6,0) -> 0.71106002 | H26: =IFERROR(H25/H6,0) -> 0.7261783 | I26: =IFERROR(I25/I6,0) -> 0.77241188 | J26: =IFERROR(J25/J6,0) -> 0.77143406 | ... O26: =IFERROR(O25/O6,0) -> 0.74263951
A28: C. COSTO DE PERSONAL
A29: Sueldos y Salarios | B29: 6211100 | C29: 28638 | D29: 24200 | E29: 24769.22 | F29: 23860 | G29: 23320 | H29: 24302.84 | I29: 24478.67 | J29: 22073.33 | K29: 22726.23 | L29: 22740 | M29: 20823.33 | N29: 18203.34 | O29: =SUM(C29:N29) -> 280134.96 | P29: =IFERROR(O29/O6,0) -> 0.13986859
A30: Asignación Familiar | B30: 6211101 | C30: 339 | D30: 226 | E30: 339 | F30: 452 | G30: 452 | H30: 452 | I30: 452 | J30: 452 | K30: 565 | L30: 452 | M30: 565 | N30: 565 | O30: =SUM(C30:N30) -> 5311 | P30: =IFERROR(O30/O6,0) -> 0.0026517293
A31: Remuneración Vacacional | B31: 6211103 | C31: 0 | D31: 0 | E31: 0 | F31: 0 | G31: 0 | H31: 0 | I31: 0 | J31: 1000 | K31: 166.67 | L31: 0 | M31: 0 | N31: 533.33 | O31: =SUM(C31:N31) -> 1700 | P31: =IFERROR(O31/O6,0) -> 0.00084879303
A32: Rem. por Feriados | B32: 6211104 | C32: 0 | D32: 0 | E32: 0 | F32: 2986.67 | G32: 1493.33 | H32: 3053.33 | I32: 4413.33 | J32: 2366.67 | K32: 0 | L32: 1186.67 | M32: 1453.33 | N32: 4063.33 | O32: =SUM(C32:N32) -> 21016.66 | P32: =IFERROR(O32/O6,0) -> 0.010493409
A33: Movilidad Personal | B33: 6211105 | C33: 100 | D33: 100 | E33: 100 | F33: 100 | G33: 100 | H33: 100 | I33: 100 | J33: 100 | K33: 100 | L33: 100 | M33: 100 | N33: 100 | O33: =SUM(C33:N33) -> 1200 | P33: =IFERROR(O33/O6,0) -> 0.00059914802
A34: Rem. Vacacional Trunca | B34: 6211106 | C34: 0 | D34: 0 | E34: 0 | F34: 379.17 | G34: 563.33 | H34: 150 | I34: 488.38 | J34: 2470 | K34: 2507.46 | L34: 646.67 | M34: 4055 | N34: 26.67 | O34: =SUM(C34:N34) -> 11286.68 | P34: =IFERROR(O34/O6,0) -> 0.0056353267
A35: Horas Extras | B35: 6212101 | C35: 2052.13 | D35: 559.31 | E35: 559.31 | F35: 559.31 | G35: 681.53 | H35: 559.31 | I35: 559.31 | J35: 559.31 | K35: 559.31 | L35: 511.81 | M35: 559.31 | N35: 620.06 | O35: =SUM(C35:N35) -> 8340.01 | P35: =IFERROR(O35/O6,0) -> 0.0041640838
A36: Gratificaciones | B36: 6214100 | C36: 818.84 | D36: 8728.04 | E36: 0 | F36: 483.33 | G36: 1000 | H36: 200 | I36: 15426.12 | J36: 1700 | K36: 2149.25 | L36: 1866.67 | M36: 5500 | N36: 14565.21 | O36: =SUM(C36:N36) -> 52437.46 | P36: =IFERROR(O36/O6,0) -> 0.0261815
A37: Bonificación Extraordinaria | B37: 6214101 | C37: 73.7 | D37: 785.52 | E37: 0 | F37: 43.5 | G37: 90 | H37: 18 | I37: 1388.36 | J37: 153 | K37: 193.43 | L37: 168 | M37: 495 | N37: 1310.87 | O37: =SUM(C37:N37) -> 4719.38 | P37: =IFERROR(O37/O6,0) -> 0.0023563393
A38: Bonificación Regular | B38: 6214103 | C38: 1859.88 | D38: 1615.48 | E38: 1693 | F38: 2400 | G38: 1400 | H38: 0 | I38: 680 | J38: 3090 | K38: 1580 | L38: 760 | M38: 700 | N38: 280 | O38: =SUM(C38:N38) -> 16058.36 | P38: =IFERROR(O38/O6,0) -> 0.0080177789
A39: Vacaciones | B39: 6215100 | C39: 4354.54 | D39: 20244.97 | E39: 0 | F39: 0 | G39: 0 | H39: 0 | I39: 0 | J39: 0 | K39: 0 | L39: 0 | M39: 0 | N39: 0 | O39: =SUM(C39:N39) -> 24599.51 | P39: =IFERROR(O39/O6,0) -> 0.01228229
A40: Otras Remuneraciones | B40: 6221100 | C40: 0 | D40: 1000 | E40: 0 | F40: 0 | G40: 0 | H40: 2020 | I40: 1580 | J40: 2260 | K40: 1583.33 | L40: 2736.67 | M40: 2010 | N40: 1406.67 | O40: =SUM(C40:N40) -> 14596.67 | P40: =IFERROR(O40/O6,0) -> 0.0072879717
A41: Capacitación | B41: 6241100 | C41: 0 | D41: 0 | E41: 0 | F41: 0 | G41: 0 | H41: 0 | I41: 0 | J41: 500 | K41: 0 | L41: 0 | M41: 0 | N41: 0 | O41: =SUM(C41:N41) -> 500 | P41: =IFERROR(O41/O6,0) -> 0.00024964501
A42: Atención al Personal | B42: 6251100 | C42: 1920 | D42: 115.81 | E42: 389.78 | F42: 237.12 | G42: 852.61 | H42: 1087.99 | I42: 1453.49 | J42: 2313.06 | K42: 554.67 | L42: 317.11 | M42: 368.04 | N42: 2519.19 | O42: =SUM(C42:N42) -> 12128.87 | P42: =IFERROR(O42/O6,0) -> 0.0060558237
A43: EsSalud | B43: 6271100 | C43: 3351.92 | D43: 4335.83 | E43: 2538.65 | F43: 2764.98 | G43: 2588.12 | H43: 2868.23 | I43: 2796.45 | J43: 2971.65 | K43: 2656.69 | L43: 2438.74 | M43: 2257.62 | N43: 2384.56 | O43: =SUM(C43:N43) -> 33953.44 | P43: =IFERROR(O43/O6,0) -> 0.016952614
...

Sheet Dashboard
A1: PERU ON ICE S.A.C. — DASHBOARD FINANCIERO 2025
A2: Análisis Visual | Ingresos | EBITDA | Márgenes | Ocupación | Costos por Hora
A4: INGRESOS 2025 | E4: EBITDA 2025 | I4: MARGEN EBITDA | M4: CHILLER | Q4: RESULTADO NETO
A5: S/ 2.00M | E5: S/ 165.7K | I5: 8.3% | M5: 26% ING. | Q5: S/ 134.7K
A8: Mes | B8: Ingresos (S/) | C8: EBITDA (S/) | D8: Costo Op. Hielo | E8: Personal | F8: % Margen EBITDA
A9: ENE | B9: ='P&L Gerencial'!C6 -> 192370.04 | C9: ='P&L Gerencial'!C101 -> 24915.24 | D9: ='P&L Gerencial'!C24 -> 48524.7 | E9: ='P&L Gerencial'!C46 -> 45063.52 | F9: =IFERROR('P&L Gerencial'!C101/'P&L Gerencial'!C6,0) -> 0.12951726
A10: FEB | B10: ='P&L Gerencial'!D6 -> 214297.38 | C10: ='P&L Gerencial'!D101 -> 32649.42 | D10: ='P&L Gerencial'!D24 -> 45607.68 | E10: ='P&L Gerencial'!D46 -> 67417.99 | F10: =IFERROR('P&L Gerencial'!D101/'P&L Gerencial'!D6,0) -> 0.15235567
A11: MAR | B11: ='P&L Gerencial'!E6 -> 159044.24 | C11: ='P&L Gerencial'!E101 -> 41786.15 | D11: ='P&L Gerencial'!E24 -> 29201.41 | E11: ='P&L Gerencial'!E46 -> 30388.96 | F11: =IFERROR('P&L Gerencial'!E101/'P&L Gerencial'!E6,0) -> 0.26273287
A12: ABR | B12: ='P&L Gerencial'!F6 -> 162394.91 | C12: ='P&L Gerencial'!F101 -> 13391.86 | D12: ='P&L Gerencial'!F24 -> 47220.97 | E12: ='P&L Gerencial'!F46 -> 38700.76 | F12: =IFERROR('P&L Gerencial'!F101/'P&L Gerencial'!F6,0) -> 0.082464777
A13: MAY | B13: ='P&L Gerencial'!G6 -> 146655.75 | C13: ='P&L Gerencial'!G101 -> 6665.3 | D13: ='P&L Gerencial'!G24 -> 42374.71 | E13: ='P&L Gerencial'!G46 -> 32704.25 | F13: =IFERROR('P&L Gerencial'!G101/'P&L Gerencial'!G6,0) -> 0.04544861
A14: JUN | B14: ='P&L Gerencial'!H6 -> 148722.4 | C14: ='P&L Gerencial'!H101 -> -6522.32 | D14: ='P&L Gerencial'!H24 -> 40723.42 | E14: ='P&L Gerencial'!H46 -> 34931.7 | F14: =IFERROR('P&L Gerencial'!H101/'P&L Gerencial'!H6,0) -> -0.043855667
A15: JUL | B15: ='P&L Gerencial'!I6 -> 185458.76 | C15: ='P&L Gerencial'!I101 -> 19179.99 | D15: ='P&L Gerencial'!I24 -> 42208.21 | E15: ='P&L Gerencial'!I46 -> 54245.31 | F15: =IFERROR('P&L Gerencial'!I101/'P&L Gerencial'!I6,0) -> 0.10341916
A16: AGO | B16: ='P&L Gerencial'!J6 -> 177730.07 | C16: ='P&L Gerencial'!J101 -> 30010.35 | D16: ='P&L Gerencial'!J24 -> 40623.04 | E16: ='P&L Gerencial'!J46 -> 43901.79 | F16: =IFERROR('P&L Gerencial'!J101/'P&L Gerencial'!J6,0) -> 0.16885353
A17: SET | B17: ='P&L Gerencial'!K6 -> 139427.16 | C17: ='P&L Gerencial'!K101 -> -12397.24 | D17: ='P&L Gerencial'!K24 -> 57081.3 | E17: ='P&L Gerencial'!K46 -> 37324.81 | F17: =IFERROR('P&L Gerencial'!K101/'P&L Gerencial'!K6,0) -> -0.088915531
A18: OCT | B18: ='P&L Gerencial'!L6 -> 144036.01 | C18: ='P&L Gerencial'!L101 -> -13120.41 | D18: ='P&L Gerencial'!L24 -> 38890.38 | E18: ='P&L Gerencial'!L46 -> 43884.16 | F18: =IFERROR('P&L Gerencial'!L101/'P&L Gerencial'!L6,0) -> -0.091091179
A19: NOV | B19: ='P&L Gerencial'!M6 -> 140103.32 | C19: ='P&L Gerencial'!M101 -> -7589.3 | D19: ='P&L Gerencial'!M24 -> 42035.44 | E19: ='P&L Gerencial'!M46 -> 40767.45 | F19: =IFERROR('P&L Gerencial'!M101/'P&L Gerencial'!M6,0) -> -0.054169309
A20: DIC | B20: ='P&L Gerencial'!N6 -> 192603.92 | C20: ='P&L Gerencial'!N101 -> 36703.55 | D20: ='P&L Gerencial'!N24 -> 40961.65 | E20: ='P&L Gerencial'!N46 -> 48008.94 | F20: =IFERROR('P&L Gerencial'!N101/'P&L Gerencial'!N6,0) -> 0.19056492
C22: ENE | D22: FEB | E22: MAR | F22: ABR | G22: MAY | H22: JUN | I22: JUL | J22: AGO | K22: SET | L22: OCT | M22: NOV | N22: DIC
A23: % Ocupación de Pista | C23: ='Indicadores Operativos'!B27 -> 0.21145238 | D23: ='Indicadores Operativos'!C27 -> 0.25993306 | E23: ='Indicadores Operativos'!D27 -> 0.17393982 | F23: ='Indicadores Operativos'!E27 -> 0.18563494 | G23: ='Indicadores Operativos'!F27 -> 0.15861796 | H23: ='Indicadores Operativos'!G27 -> 0.16914206 | I23: ='Indicadores Operativos'!H27 -> 0.20490392 | J23: ='Indicadores Operativos'!I27 -> 0.19130246 | ... N23: ='Indicadores Operativos'!M27 -> 0.2151747
A24: Ingreso por Hora Disponible (S/) | C24: ='Indicadores Operativos'!B39 -> 642.30397 | D24: ='Indicadores Operativos'!C39 -> 789.59978 | E24: ='Indicadores Operativos'!D39 -> 528.38618 | F24: ='Indicadores Operativos'!E39 -> 563.87122 | G24: ='Indicadores Operativos'!F39 -> 481.7863 | H24: ='Indicadores Operativos'!G39 -> 513.72159 | I24: ='Indicadores Operativos'!H39 -> 622.34483 | J24: ='Indicadores Operativos'!I39 -> 581.00709 | ... N24: ='Indicadores Operativos'!M39 -> 653.55928
A25: Costo Total por Hora Disponible (S/) | C25: ='Indicadores Operativos'!B38 -> 559.11452 | D25: ='Indicadores Operativos'!C38 -> 669.29978 | E25: ='Indicadores Operativos'!D38 -> 389.56176 | F25: ='Indicadores Operativos'!E38 -> 517.3717 | G25: ='Indicadores Operativos'!F38 -> 459.88978 | H25: ='Indicadores Operativos'!G38 -> 536.25119 | I25: ='Indicadores Operativos'!H38 -> 557.98245 | J25: ='Indicadores Operativos'!I38 -> 482.90199 | ... N25: ='Indicadores Operativos'!M38 -> 529.01381
A26: Margen S/ | C26: =+C24-C25 -> 83.189449 | D26: =+D24-D25 -> 120.3 | E26: =+E24-E25 -> 138.82442 | F26: =+F24-F25 -> 46.499514 | G26: =+G24-G25 -> 21.896518 | H26: =+H24-H25 -> -22.529603 | I26: =+I24-I25 -> 64.362383 | J26: =+J24-J25 -> 98.1051 | ... N26: =+N24-N25 -> 124.54547
A27: Margen % | C27: =+C25/C24*100 -> 87.048274 | D27: =+D25/D24*100 -> 84.764433 | E27: =+E25/E24*100 -> 73.726713 | F27: =+F25/F24*100 -> 91.753522 | G27: =+G25/G24*100 -> 95.455139 | H27: =+H25/H24*100 -> 104.38557 | I27: =+I25/I24*100 -> 89.658084 | J27: =+J25/J24*100 -> 83.114647 | ... N27: =+N25/N24*100 -> 80.943508

Sheet Comparativo vs PSTO
A1: PERU ON ICE — COMPARATIVO GERENCIAL: P&L 2026 REAL vs PRESUPUESTO 2026 (SIN IGV)
A2: Ppto 2026 = Proyectado ENE-DIC
A3: ▌ PARTE 1 — RESUMEN ANUAL
A4: CONCEPTO | B4: REAL 2026 (S/) | C4: PL 2025 (S/) | D4: PPTO 2026 (S/) | E4: VAR. (S/) | F4: VAR. (%) | G4: % REV 2025 | H4: % REV 2026 | I4: TENDENCIA
A5: A. INGRESOS
A6: Ingresos por Servicios de Pista | B6: ='P&L Gerencial'!O6 -> 2002844 | C6: ='P&L Gerencial'!O6 -> 2002844 | D6: ='Datos 2026'!O4 -> 2114576.3 | E6: =D6-B6 -> 111732.34 | F6: =IFERROR((D6-B6)/ABS(B6),0) -> 0.055786842 | G6: =IFERROR(B6/'P&L Gerencial'!O6,0) -> 1 | H6: =IFERROR(D6/2114576.3,0) -> 1 | I6: ▲ Mayor gasto
A8: B. COSTOS OPERATIVOS DEL HIELO
A9: Energía Eléctrica | B9: ='P&L Gerencial'!O11 -> 238552.34 | C9: ='P&L Gerencial'!O11 -> 238552.34 | D9: ='Datos 2026'!O38 -> 244281.07 | E9: =D9-B9 -> 5728.73 | F9: =IFERROR((D9-B9)/ABS(B9),0) -> 0.024014562 | G9: =IFERROR(B9/'P&L Gerencial'!O6,0) -> 0.1191068 | H9: =IFERROR(D9/2114576.3,0) -> 0.11552247 | I9: ▲ Mayor gasto
A10: Alquiler Chiller (Refrigeración) | B10: ='P&L Gerencial'!O12 -> 209000 | C10: ='P&L Gerencial'!O12 -> 209000 | D10: ='Datos 2026'!O35 -> 209000 | E10: =D10-B10 -> 0 | F10: =IFERROR((D10-B10)/ABS(B10),0) -> 0 | G10: =IFERROR(B10/'P&L Gerencial'!O6,0) -> 0.10435161 | H10: =IFERROR(D10/2114576.3,0) -> 0.098837767 | I10: ══
A11: Agua | B11: ='P&L Gerencial'!O13 -> 8174.44 | C11: ='P&L Gerencial'!O13 -> 8174.44 | D11: ='Datos 2026'!O39 -> 8355.47 | E11: =D11-B11 -> 181.03 | F11: =IFERROR((D11-B11)/ABS(B11),0) -> 0.02214586 | G11: =IFERROR(B11/'P&L Gerencial'!O6,0) -> 0.0040814163 | H11: =IFERROR(D11/2114576.3,0) -> 0.0039513684 | I11: ▲ Mayor gasto
A12: Mantenimiento Local | B12: ='P&L Gerencial'!O14 -> 22303.78 | C12: ='P&L Gerencial'!O14 -> 22303.78 | D12: ='Datos 2026'!O33 -> 23413.97 | E12: =D12-B12 -> 1110.19 | F12: =IFERROR((D12-B12)/ABS(B12),0) -> 0.049775868 | G12: =IFERROR(B12/'P&L Gerencial'!O6,0) -> 0.011136055 | H12: =IFERROR(D12/2114576.3,0) -> 0.011072653 | I12: ▲ Mayor gasto
A13: Otros costos operativos | B13: ='P&L Gerencial'!O16+'P&L Gerencial'!O17+'P&L Gerencial'!O18+'P&L Gerencial'!O19+'P&L Gerencial'!O20+'P&L Gerencial'!O21+'P&L Gerencial'!O22+'P&L Gerencial'!O23 -> 33722.35 | C13: ='P&L Gerencial'!O16+'P&L Gerencial'!O17+'P&L Gerencial'!O18+'P&L Gerencial'!O19+'P&L Gerencial'!O20+'P&L Gerencial'!O21+'P&L Gerencial'!O22+'P&L Gerencial'!O23 -> 33722.35 | D13: ='Datos 2026'!O53+'Datos 2026'!O54+'Datos 2026'!O64+'Datos 2026'!O66+'Datos 2026'!O67+'Datos 2026'!O69+'Datos 2026'!O75+'Datos 2026'!O76 -> 35032.41 | E13: =D13-B13 -> 1310.06 | F13: =IFERROR((D13-B13)/ABS(B13),0) -> 0.03884842 | G13: =IFERROR(B13/'P&L Gerencial'!O6,0) -> 0.016837233 | H13: =IFERROR(D13/2114576.3,0) -> 0.016567106 | I13: ▲ Mayor gasto
A14: TOTAL Costos Op. Hielo | B14: ='P&L Gerencial'!O24 -> 515452.91 | C14: ='P&L Gerencial'!O24 -> 515452.91 | D14: =SUM(D9:D13) -> 520082.92 | E14: =D14-C14 -> 4630.01 | F14: =IFERROR((D14-C14)/ABS(C14),0) -> 0.0089824112 | G14: =IFERROR(C14/'P&L Gerencial'!O6,0) -> 0.25736049 | H14: =IFERROR(D14/2114576.32,0) -> 0.24595136 | I14: ▲ Mayor gasto
A15: ★ UTILIDAD BRUTA OPERATIVA | B15: ='P&L Gerencial'!O25 -> 1487391.1 | C15: ='P&L Gerencial'!O25 -> 1487391.1 | D15: =+D6-D14 -> 1594493.4 | E15: =D15-C15 -> 107102.33 | F15: =IFERROR((D15-C15)/ABS(C15),0) -> 0.07200684 | G15: =IFERROR(C15/'P&L Gerencial'!O6,0) -> 0.74263951 | H15: =IFERROR(D15/2114576.32,0) -> 0.75404863 | I15: ▲ Mejora
A17: C. COSTO DE PERSONAL
A18: Sueldos y Salarios | B18: ='P&L Gerencial'!O29 -> 280134.96 | C18: ='P&L Gerencial'!O29 -> 280134.96 | D18: ='Datos 2026'!O7 -> 291499.81 | E18: =D18-B18 -> 11364.85 | F18: =IFERROR((D18-B18)/ABS(B18),0) -> 0.040569196 | G18: =IFERROR(B18/'P&L Gerencial'!O6,0) -> 0.13986859 | H18: =IFERROR(D18/2114576.3,0) -> 0.13785259 | I18: ▲ Mayor gasto
A19: Gratificaciones + CTS + EsSalud | B19: ='P&L Gerencial'!O36+'P&L Gerencial'!O45+'P&L Gerencial'!O43 -> 111592.03 | C19: ='P&L Gerencial'!O36+'P&L Gerencial'!O45+'P&L Gerencial'!O43 -> 111592.03 | D19: ='Datos 2026'!O14+'Datos 2026'!O23+'Datos 2026'!O21 -> 114739.18 | E19: =D19-B19 -> 3147.15 | F19: =IFERROR((D19-B19)/ABS(B19),0) -> 0.028202283 | G19: =IFERROR(B19/'P&L Gerencial'!O6,0) -> 0.055716787 | H19: =IFERROR(D19/2114576.3,0) -> 0.054261073 | I19: ▲ Mayor gasto
A20: Otras remuneraciones y cargas | B20: ='P&L Gerencial'!O30+'P&L Gerencial'!O31+'P&L Gerencial'!O32+'P&L Gerencial'!O33+'P&L Gerencial'!O34+'P&L Gerencial'!O35+'P&L Gerencial'!O37+'P&L Gerencial'!O38+'P&L Gerencial'!O39+'P&L Gerencial'!O40+'P&L Gerencial'!O41+'P&L Gerencial'!O42+'P&L Gerencial'!O44 -> 125612.65 | C20: ='P&L Gerencial'!O30+'P&L Gerencial'!O31+'P&L Gerencial'!O32+'P&L Gerencial'!O33+'P&L Gerencial'!O34+'P&L Gerencial'!O35+'P&L Gerencial'!O37+'P&L Gerencial'!O38+'P&L Gerencial'!O39+'P&L Gerencial'!O40+'P&L Gerencial'!O41+'P&L Gerencial'!O42+'P&L Gerencial'!O44 -> 125612.65 | D20: ='Datos 2026'!O8+'Datos 2026'!O9+'Datos 2026'!O10+'Datos 2026'!O11+'Datos 2026'!O12+'Datos 2026'!O13+'Datos 2026'!O15+'Datos 2026'!O16+'Datos 2026'!O17+'Datos 2026'!O18+'Datos 2026'!O19+'Datos 2026'!O20+'Datos 2026'!O22 -> 126960.03 | E20: =D20-B20 -> 1347.38 | F20: =IFERROR((D20-B20)/ABS(B20),0) -> 0.010726467 | G20: =IFERROR(B20/'P&L Gerencial'!O6,0) -> 0.062717142 | H20: =IFERROR(D20/2114576.3,0) -> 0.060040411 | I20: ▲ Mayor gasto
A21: TOTAL Personal | B21: ='P&L Gerencial'!O46 -> 517339.64 | C21: ='P&L Gerencial'!O46 -> 517339.64 | D21: =SUM(D18:D20) -> 533199.02 | E21: =D21-C21 -> 15859.38 | F21: =IFERROR((D21-C21)/ABS(C21),0) -> 0.030655644 | G21: =IFERROR(C21/'P&L Gerencial'!O6,0) -> 0.25830252 | H21: =IFERROR(D21/2114576.32,0) -> 0.25215407 | I21: ▲ Mayor gasto
A23: D. GASTOS COMERCIALES
A24: Comisión Tarjeta de Crédito | B24: ='P&L Gerencial'!O56 -> 42784.83 | C24: ='P&L Gerencial'!O56 -> 42784.83 | D24: ='Datos 2026'!O73 -> 44490.87 | E24: =D24-B24 -> 1706.04 | F24: =IFERROR((D24-B24)/ABS(B24),0) -> 0.039874881 | G24: =IFERROR(B24/'P&L Gerencial'!O6,0) -> 0.021362039 | H24: =IFERROR(D24/2114576.3,0) -> 0.021040087 | I24: ▲ Mayor gasto
A25: Publicidad y Marketing | B25: ='P&L Gerencial'!O51+'P&L Gerencial'!O52+'P&L Gerencial'!O53 -> 22960.12 | C25: ='P&L Gerencial'!O51+'P&L Gerencial'!O52+'P&L Gerencial'!O53 -> 22960.12 | D25: ='Datos 2026'!O41+'Datos 2026'!O47+'Datos 2026'!O48 -> 25006.55 | E25: =D25-B25 -> 2046.43 | F25: =IFERROR((D25-B25)/ABS(B25),0) -> 0.089129761 | G25: =IFERROR(B25/'P&L Gerencial'!O6,0) -> 0.011463759 | H25: =IFERROR(D25/2114576.3,0) -> 0.011825797 | I25: ▲ Mayor gasto
A26: Comisión Ventas + Eventos | B26: ='P&L Gerencial'!O54+'P&L Gerencial'!O55 -> 39954.44 | C26: ='P&L Gerencial'!O54+'P&L Gerencial'!O55 -> 39954.44 | D26: ='Datos 2026'!O49+'Datos 2026'!O52 -> 41561.89 | E26: =D26-B26 -> 1607.45 | F26: =IFERROR((D26-B26)/ABS(B26),0) -> 0.040232074 | G26: =IFERROR(B26/'P&L Gerencial'!O6,0) -> 0.019948853 | H26: =IFERROR(D26/2114576.3,0) -> 0.019654949 | I26: ▲ Mayor gasto
A27: TOTAL Comercial | B27: ='P&L Gerencial'!O57 -> 105699.39 | C27: ='P&L Gerencial'!O57 -> 105699.39 | D27: =SUM(D24:D26) -> 111059.31 | E27: =D27-C27 -> 5359.92 | F27: =IFERROR((D27-C27)/ABS(C27),0) -> 0.050709091 | G27: =IFERROR(C27/'P&L Gerencial'!O6,0) -> 0.052774651 | H27: =IFERROR(D27/2114576.32,0) -> 0.052520833 | I27: ▲ Mayor gasto
A29: E. GASTOS ADMINISTRATIVOS
A30: Asesorías (Admin+Legal+Contab) | B30: ='P&L Gerencial'!O61+'P&L Gerencial'!O62+'P&L Gerencial'!O63+'P&L Gerencial'!O64 -> 39040 | C30: ='P&L Gerencial'!O61+'P&L Gerencial'!O62+'P&L Gerencial'!O63+'P&L Gerencial'!O64 -> 39040 | D30: ='Datos 2026'!O29+'Datos 2026'!O30+'Datos 2026'!O31+'Datos 2026'!O32 -> 39604.5 | E30: =D30-B30 -> 564.5 | F30: =IFERROR((D30-B30)/ABS(B30),0) -> 0.014459529 | G30: =IFERROR(B30/'P&L Gerencial'!O6,0) -> 0.019492282 | H30: =IFERROR(D30/2114576.3,0) -> 0.018729284 | I30: ▲ Mayor gasto
A31: Tributos y Seguros | B31: ='P&L Gerencial'!O67+'P&L Gerencial'!O70 -> 17646.08 | C31: ='P&L Gerencial'!O67+'P&L Gerencial'!O70 -> 17646.08 | D31: ='Datos 2026'!O57+'Datos 2026'!O60 -> 18271.64 | E31: =D31-B31 -> 625.56 | F31: =IFERROR((D31-B31)/ABS(B31),0) -> 0.035450366 | G31: =IFERROR(B31/'P&L Gerencial'!O6,0) -> 0.0088105116 | H31: =IFERROR(D31/2114576.3,0) -> 0.0086408043 | I31: ▲ Mayor gasto
A32: Otros administrativos | B32: ='P&L Gerencial'!O65+'P&L Gerencial'!O66+'P&L Gerencial'!O68+'P&L Gerencial'!O69+'P&L Gerencial'!O71+'P&L Gerencial'!O72+'P&L Gerencial'!O73+'P&L Gerencial'!O74+'P&L Gerencial'!O75+'P&L Gerencial'!O76+'P&L Gerencial'!O77+'P&L Gerencial'!O78+'P&L Gerencial'!O79+'P&L Gerencial'!O80 -> 19243.26 | C32: ='P&L Gerencial'!O65+'P&L Gerencial'!O66+'P&L Gerencial'!O68+'P&L Gerencial'!O69+'P&L Gerencial'!O71+'P&L Gerencial'!O72+'P&L Gerencial'!O73+'P&L Gerencial'!O74+'P&L Gerencial'!O75+'P&L Gerencial'!O76+'P&L Gerencial'!O77+'P&L Gerencial'!O78+'P&L Gerencial'!O79+'P&L Gerencial'!O80 -> 19243.26 | D32: ='Datos 2026'!O55+'Datos 2026'!O56+'Datos 2026'!O58+'Datos 2026'!O59+'Datos 2026'!O61+'Datos 2026'!O62+'Datos 2026'!O65+'Datos 2026'!O68+'Datos 2026'!O70+'Datos 2026'!O71+'Datos 2026'!O72+'Datos 2026'!O74+'Datos 2026'!O77+'Datos 2026'!O78 -> 19835.77 | E32: =D32-B32 -> 592.51 | F32: =IFERROR((D32-B32)/ABS(B32),0) -> 0.030790521 | G32: =IFERROR(B32/'P&L Gerencial'!O6,0) -> 0.0096079677 | H32: =IFERROR(D32/2114576.3,0) -> 0.0093804939 | I32: ▲ Mayor gasto
A33: TOTAL Administrativo | B33: ='P&L Gerencial'!O81 -> 75929.34 | C33: ='P&L Gerencial'!O81 -> 75929.34 | D33: =SUM(D30:D32) -> 77711.91 | E33: =D33-C33 -> 1782.57 | F33: =IFERROR((D33-C33)/ABS(C33),0) -> 0.023476696 | G33: =IFERROR(C33/'P&L Gerencial'!O6,0) -> 0.037910762 | H33: =IFERROR(D33/2114576.32,0) -> 0.036750582 | I33: ▲ Mayor gasto
A35: F. GASTOS FIJOS / ESTRUCTURA
A36: Alquiler Local | B36: ='P&L Gerencial'!O84 -> 583542.5 | C36: ='P&L Gerencial'!O84 -> 583542.5 | D36: ='Datos 2026'!O36 -> 593198.85 | E36: =D36-B36 -> 9656.35 | F36: =IFERROR((D36-B36)/ABS(B36),0) -> 0.016547809 | G36: =IFERROR(B36/'P&L Gerencial'!O6,0) -> 0.29135695 | H36: =IFERROR(D36/2114576.3,0) -> 0.28052847 | I36: ▲ Mayor gasto
A37: Servicio de Seguridad | B37: ='P&L Gerencial'!O92 -> 16010.17 | C37: ='P&L Gerencial'!O92 -> 16010.17 | D37: ='Datos 2026'!O50 -> 16628.34 | E37: =D37-B37 -> 618.17 | F37: =IFERROR((D37-B37)/ABS(B37),0) -> 0.038611083 | G37: =IFERROR(B37/'P&L Gerencial'!O6,0) -> 0.0079937181 | H37: =IFERROR(D37/2114576.3,0) -> 0.0078636746 | I37: ▲ Mayor gasto
A38: Otros servicios estructura | B38: ='P&L Gerencial'!O85+'P&L Gerencial'!O86+'P&L Gerencial'!O87+'P&L Gerencial'!O88+'P&L Gerencial'!O89+'P&L Gerencial'!O90+'P&L Gerencial'!O91+'P&L Gerencial'!O93+'P&L Gerencial'!O94+'P&L Gerencial'!O95+'P&L Gerencial'!O96+'P&L Gerencial'!O97+'P&L Gerencial'!O98 -> 23197.42 | C38: ='P&L Gerencial'!O85+'P&L Gerencial'!O86+'P&L Gerencial'!O87+'P&L Gerencial'!O88+'P&L Gerencial'!O89+'P&L Gerencial'!O90+'P&L Gerencial'!O91+'P&L Gerencial'!O93+'P&L Gerencial'!O94+'P&L Gerencial'!O95+'P&L Gerencial'!O96+'P&L Gerencial'!O97+'P&L Gerencial'!O98 -> 23197.42 | D38: ='Datos 2026'!O37+'Datos 2026'!O40+'Datos 2026'!O42+'Datos 2026'!O43+'Datos 2026'!O44+'Datos 2026'!O45+'Datos 2026'!O46+'Datos 2026'!O51+'Datos 2026'!O24+'Datos 2026'!O25+'Datos 2026'!O26+'Datos 2026'!O27+'Datos 2026'!O28 -> 23551.01 | E38: =D38-B38 -> 353.59 | F38: =IFERROR((D38-B38)/ABS(B38),0) -> 0.015242643 | G38: =IFERROR(B38/'P&L Gerencial'!O6,0) -> 0.01158224 | H38: =IFERROR(D38/2114576.3,0) -> 0.01113746 | I38: ▲ Mayor gasto
A39: TOTAL Estructura | B39: ='P&L Gerencial'!O99 -> 622750.09 | C39: ='P&L Gerencial'!O99 -> 622750.09 | D39: =D36+D37+D38 -> 633378.2 | E39: =D39-B39 -> 10628.11 | F39: =IFERROR((D39-B39)/ABS(B39),0) -> 0.017066413 | G39: =IFERROR(B39/'P&L Gerencial'!O6,0) -> 0.3109329 | H39: =IFERROR(D39/2114576.3,0) -> 0.2995296 | I39: ▲ Mayor gasto
A41: ★★ EBITDA | B41: ='P&L Gerencial'!O101 -> 165672.59 | C41: ='P&L Gerencial'!O101 -> 165672.59 | D41: =+D15-D21-D27-D33-D39 -> 239144.94 | E41: =D41-C41 -> 73472.35 | F41: =IFERROR((D41-C41)/ABS(C41),0) -> 0.44347921 | G41: =IFERROR(C41/'P&L Gerencial'!O6,0) -> 0.082718671 | H41: =IFERROR(D41/2114576.32,0) -> 0.11309355 | I41: ▲ Mejora
A42: Margen EBITDA (%) | B42: =IFERROR(B41/B6,0) -> 0.082718671 | C42: =IFERROR(C41/C6,0) -> 0.082718671 | D42: =IFERROR(D41/D6,0) -> 0.11309355 | E42: =IFERROR(D42-B42,0) -> 0.030374879 | F42: =IFERROR((D42-B42)/ABS(B42),0) -> 0.36720705 | G42: =IFERROR(C42/'P&L Gerencial'!O6,0) -> 4.1300607e-08 | H42: =IFERROR(D42/2114576.32,0) -> 5.3482841e-08 | I42: ▲ Mejora
A44: G. DEPRECIACIÓN
A45: TOTAL Depreciación | B45: ='P&L Gerencial'!O111 -> 7526.73 | C45: ='P&L Gerencial'!O111 -> 7526.73 | D45: ='Datos 2026'!O81+'Datos 2026'!O82+'Datos 2026'!O83+'Datos 2026'!O84+'Datos 2026'!O85 -> 7526.73 | E45: =D45-B45 -> 0 | F45: =IFERROR((D45-B45)/ABS(B45),0) -> -2.4167061e-16 | G45: =IFERROR(B45/'P&L Gerencial'!O6,0) -> 0.0037580212 | H45: =IFERROR(D45/2114576.3,0) -> 0.0035594507 | I45: ══
A46: EBIT — Utilidad Operativa | B46: ='P&L Gerencial'!O112 -> 158145.86 | C46: ='P&L Gerencial'!O112 -> 158145.86 | D46: =+D41-D45 -> 231618.21 | E46: =D46-C46 -> 73472.35 | F46: =IFERROR((D46-C46)/ABS(C46),0) -> 0.46458598 | G46: =IFERROR(C46/'P&L Gerencial'!O6,0) -> 0.07896065 | H46: =IFERROR(D46/2114576.32,0) -> 0.1095341 | I46: ▲ Mayor gasto
A48: H. RESULTADO FINANCIERO NETO
...

Sheet Indicadores Operativos
A1: PERU ON ICE — DRIVERS OPERATIVOS Y MODELO DE INGRESOS
A2: Aforo: 40 pers. pista / 98 local | Chiller: 24/7
A4: MÉTRICA / PARÁMETRO | B4: ENE | C4: FEB | D4: MAR | E4: ABR | F4: MAY | G4: JUN | H4: JUL | I4: AGO | J4: SET | K4: OCT | L4: NOV | M4: DIC | N4: TOTAL / PROM. | O4: TOTAL / PROM.
A5: 1. ESTRUCTURA DE TARIFAS Y MEZCLA DE PRODUCTOS
A6: PRODUCTO/SERVICIO | B6: PRECIO | C6: DESCRIPCIÓN | D6: SEGMENTO
A7: Entrada 25 minutos | B7: S/ 35 | C7: Tarifa estándar público general
A8: Entrada 55 minutos | B8: S/ 60 | C8: Tarifa extendida público general
A9: Membresía Coach | B9: S/ 150/mes | C9: Acceso 5AM-10PM ilimitado
A10: Membresía Deportistas | B10: S/ 350/mes | C10: Clases L/M 4:40-9:30 PM | M/J 4:30-6 PM + Free Practice 5-9 AM
A11: Salón Off-Ice | B11: S/ 30 | C11: Uso del salón sin acceso a pista
A13: 2. TICKET PROMEDIO REAL Y VISITAS MENSUALES
A14: Ticket Promedio Real (S/) — Calibrado Feb 2025 | B14: 41.51 | C14: 41.51 | D14: 41.51 | E14: 41.51 | F14: 41.51 | G14: 41.51 | H14: 41.51 | I14: 41.51 | J14: 41.51 | K14: 41.51 | L14: 41.51 | M14: 41.51 | O14: =SUM(B14:N14) -> 498.12
A15: Visitas al Mes (real/estimado) | B15: 4634 | C15: 5162 | D15: 3831 | E15: 3912 | F15: 3533 | G15: 3583 | H15: 4468 | I15: 4282 | J15: 3359 | K15: 3470 | L15: 3375 | M15: 4640 | O15: =SUM(B15:N15) -> 48249
C16: ↑ Confirmado Feb 2025
A17: Ingresos Calculados (Visitas × Ticket) | B17: =B15*B14 -> 192357.34 | C17: =C15*C14 -> 214274.62 | D17: =D15*D14 -> 159024.81 | E17: =E15*E14 -> 162387.12 | F17: =F15*F14 -> 146654.83 | G17: =G15*G14 -> 148730.33 | H17: =H15*H14 -> 185466.68 | I17: =I15*I14 -> 177745.82 | ... M17: =M15*M14 -> 192606.4 | O17: =SUM(B17:N17) -> 2002816
A18: Ingresos Reales P&L (vínculo) | B18: ='P&L Gerencial'!C6 -> 192370.04 | C18: ='P&L Gerencial'!D6 -> 214297.38 | D18: ='P&L Gerencial'!E6 -> 159044.24 | E18: ='P&L Gerencial'!F6 -> 162394.91 | F18: ='P&L Gerencial'!G6 -> 146655.75 | G18: ='P&L Gerencial'!H6 -> 148722.4 | H18: ='P&L Gerencial'!I6 -> 185458.76 | I18: ='P&L Gerencial'!J6 -> 177730.07 | ... M18: ='P&L Gerencial'!N6 -> 192603.92 | O18: =SUM(B18:N18) -> 2002844
A20: 3. CAPACIDAD DE PISTA Y ANÁLISIS DE OCUPACIÓN
A21: HORARIO: Atención al público 10AM-10PM (12 hrs/día) | Clases L/M: 4:40PM-9:30PM (pista cerrada a público) | Clases M/J: 4:30PM-6PM (pista cerrada a público) | Mantenimiento: 1PM y 6PM (~15 min c/u) | Chiller: 24/7 | Aforo pista: 40 personas
A22: Horas Disponibles al Público (calculadas por calendario) | B22: 299.5 | C22: 271.4 | D22: 301 | E22: 288 | F22: 304.4 | G22: 289.5 | H22: 298 | I22: 305.9 | J22: 288 | K22: 299.5 | L22: 294.4 | M22: 294.7 | O22: =SUM(B22:N22) -> 3534.3
A23: Aforo Máximo Pista (personas simultáneas) | B23: 40 | C23: 40 | D23: 40 | E23: 40 | F23: 40 | G23: 40 | H23: 40 | I23: 40 | J23: 40 | K23: 40 | L23: 40 | M23: 40 | O23: =SUM(B23:N23) -> 480
A24: Duración Prom. Sesión (hrs) — calculada del mix Simulador: =(vol_25*(25/60)+vol_55*(55/60))/(vol_25+vol_55) | B24: =IFERROR((Simulador!B16*(25/60)+Simulador!B17*(55/60))/(Simulador!B16+Simulador!B17),25/60) -> 0.54665504 | C24: =IFERROR((Simulador!B16*(25/60)+Simulador!B17*(55/60))/(Simulador!B16+Simulador!B17),25/60) -> 0.54665504 | D24: =IFERROR((Simulador!B16*(25/60)+Simulador!B17*(55/60))/(Simulador!B16+Simulador!B17),25/60) -> 0.54665504 | E24: =IFERROR((Simulador!B16*(25/60)+Simulador!B17*(55/60))/(Simulador!B16+Simulador!B17),25/60) -> 0.54665504 | F24: =IFERROR((Simulador!B16*(25/60)+Simulador!B17*(55/60))/(Simulador!B16+Simulador!B17),25/60) -> 0.54665504 | G24: =IFERROR((Simulador!B16*(25/60)+Simulador!B17*(55/60))/(Simulador!B16+Simulador!B17),25/60) -> 0.54665504 | H24: =IFERROR((Simulador!B16*(25/60)+Simulador!B17*(55/60))/(Simulador!B16+Simulador!B17),25/60) -> 0.54665504 | I24: =IFERROR((Simulador!B16*(25/60)+Simulador!B17*(55/60))/(Simulador!B16+Simulador!B17),25/60) -> 0.54665504 | J24: =IFERROR((Simulador!B16*(25/60)+Simulador!B17*(55/60))/(Simulador!B16+Simulador!B17),25/60) -> 0.54665504 | K24: =IFERROR((Simulador!B16*(25/60)+Simulador!B17*(55/60))/(Simulador!B16+Simulador!B17),25/60) -> 0.54665504 | L24: =IFERROR((Simulador!B16*(25/60)+Simulador!B17*(55/60))/(Simulador!B16+Simulador!B17),25/60) -> 0.54665504 | M24: =IFERROR((Simulador!B16*(25/60)+Simulador!B17*(55/60))/(Simulador!B16+Simulador!B17),25/60) -> 0.54665504 | O24: =AVERAGE(B24:N24) -> 0.54665504
A25: Capacidad Máxima (person-horas / mes) | B25: =B22*B23 -> 11980 | C25: =C22*C23 -> 10856 | D25: =D22*D23 -> 12040 | E25: =E22*E23 -> 11520 | F25: =F22*F23 -> 12176 | G25: =G22*G23 -> 11580 | H25: =H22*H23 -> 11920 | I25: =I22*I23 -> 12236 | ... M25: =M22*M23 -> 11788 | O25: =SUM(B25:N25) -> 141372
A26: Person-Horas Vendidas (visitas × duración prom.) | B26: =B15*B24 -> 2533.1995 | C26: =C15*C24 -> 2821.8333 | D26: =D15*D24 -> 2094.2355 | E26: =E15*E24 -> 2138.5145 | F26: =F15*F24 -> 1931.3323 | G26: =G15*G24 -> 1958.665 | H26: =H15*H24 -> 2442.4547 | I26: =I15*I24 -> 2340.7769 | ... M26: =M15*M24 -> 2536.4794 | O26: =SUM(B26:N26) -> 26375.559
A27: ★ % Ocupación de Pista | B27: =IFERROR(B26/B25,0) -> 0.21145238 | C27: =IFERROR(C26/C25,0) -> 0.25993306 | D27: =IFERROR(D26/D25,0) -> 0.17393982 | E27: =IFERROR(E26/E25,0) -> 0.18563494 | F27: =IFERROR(F26/F25,0) -> 0.15861796 | G27: =IFERROR(G26/G25,0) -> 0.16914206 | H27: =IFERROR(H26/H25,0) -> 0.20490392 | I27: =IFERROR(I26/I25,0) -> 0.19130246 | ... M27: =IFERROR(M26/M25,0) -> 0.2151747 | O27: =AVERAGE(B27:N27) -> 0.18704204
A28: Personas Promedio Simultáneas en Pista | B28: =IFERROR(B26/B22,0) -> 8.4580951 | C28: =IFERROR(C26/C22,0) -> 10.397323 | D28: =IFERROR(D26/D22,0) -> 6.9575929 | E28: =IFERROR(E26/E22,0) -> 7.4253977 | F28: =IFERROR(F26/F22,0) -> 6.3447184 | G28: =IFERROR(G26/G22,0) -> 6.7656823 | H28: =IFERROR(H26/H22,0) -> 8.1961568 | I28: =IFERROR(I26/I22,0) -> 7.6520984 | ... M28: =IFERROR(M26/M22,0) -> 8.6069881 | O28: =AVERAGE(B28:N28) -> 7.4816816
A29: Visitas por Hora Disponible | B29: =IFERROR(B15/B22,0) -> 15.472454 | C29: =IFERROR(C15/C22,0) -> 19.019897 | D29: =IFERROR(D15/D22,0) -> 12.727575 | E29: =IFERROR(E15/E22,0) -> 13.583333 | F29: =IFERROR(F15/F22,0) -> 11.606439 | G29: =IFERROR(G15/G22,0) -> 12.376511 | H29: =IFERROR(H15/H22,0) -> 14.993289 | I29: =IFERROR(I15/I22,0) -> 13.998039 | ... M29: =IFERROR(M15/M22,0) -> 15.744825 | O29: =AVERAGE(B29:N29) -> 13.686294
A31: 4. ANÁLISIS DE INGRESO Y COSTO POR HORA — KPIs CLAVE
A32: Costos Operativos Hielo (del P&L) | B32: ='P&L Gerencial'!C24 -> 48524.7 | C32: ='P&L Gerencial'!D24 -> 45607.68 | D32: ='P&L Gerencial'!E24 -> 29201.41 | E32: ='P&L Gerencial'!F24 -> 47220.97 | F32: ='P&L Gerencial'!G24 -> 42374.71 | G32: ='P&L Gerencial'!H24 -> 40723.42 | H32: ='P&L Gerencial'!I24 -> 42208.21 | I32: ='P&L Gerencial'!J24 -> 40623.04 | ... M32: ='P&L Gerencial'!N24 -> 40961.65 | O32: =SUM(B32:N32) -> 515452.91
A33: Costo de Personal (del P&L) | B33: ='P&L Gerencial'!C46 -> 45063.52 | C33: ='P&L Gerencial'!D46 -> 67417.99 | D33: ='P&L Gerencial'!E46 -> 30388.96 | E33: ='P&L Gerencial'!F46 -> 38700.76 | F33: ='P&L Gerencial'!G46 -> 32704.25 | G33: ='P&L Gerencial'!H46 -> 34931.7 | H33: ='P&L Gerencial'!I46 -> 54245.31 | I33: ='P&L Gerencial'!J46 -> 43901.79 | ... M33: ='P&L Gerencial'!N46 -> 48008.94 | O33: =SUM(B33:N33) -> 517339.64
A34: Costos Totales Operativos (sin Deprec.) | B34: ='P&L Gerencial'!C24+'P&L Gerencial'!C46+'P&L Gerencial'!C57+'P&L Gerencial'!C81+'P&L Gerencial'!C99 -> 167454.8 | C34: ='P&L Gerencial'!D24+'P&L Gerencial'!D46+'P&L Gerencial'!D57+'P&L Gerencial'!D81+'P&L Gerencial'!D99 -> 181647.96 | D34: ='P&L Gerencial'!E24+'P&L Gerencial'!E46+'P&L Gerencial'!E57+'P&L Gerencial'!E81+'P&L Gerencial'!E99 -> 117258.09 | E34: ='P&L Gerencial'!F24+'P&L Gerencial'!F46+'P&L Gerencial'!F57+'P&L Gerencial'!F81+'P&L Gerencial'!F99 -> 149003.05 | F34: ='P&L Gerencial'!G24+'P&L Gerencial'!G46+'P&L Gerencial'!G57+'P&L Gerencial'!G81+'P&L Gerencial'!G99 -> 139990.45 | G34: ='P&L Gerencial'!H24+'P&L Gerencial'!H46+'P&L Gerencial'!H57+'P&L Gerencial'!H81+'P&L Gerencial'!H99 -> 155244.72 | H34: ='P&L Gerencial'!I24+'P&L Gerencial'!I46+'P&L Gerencial'!I57+'P&L Gerencial'!I81+'P&L Gerencial'!I99 -> 166278.77 | I34: ='P&L Gerencial'!J24+'P&L Gerencial'!J46+'P&L Gerencial'!J57+'P&L Gerencial'!J81+'P&L Gerencial'!J99 -> 147719.72 | ... M34: ='P&L Gerencial'!N24+'P&L Gerencial'!N46+'P&L Gerencial'!N57+'P&L Gerencial'!N81+'P&L Gerencial'!N99 -> 155900.37 | O34: =SUM(B34:N34) -> 1837171.4
A36: ⚡ Costo Operativo Hielo por Hora Disponible (S/) | B36: =IFERROR(B32/B22,0) -> 162.01903 | C36: =IFERROR(C32/C22,0) -> 168.04598 | D36: =IFERROR(D32/D22,0) -> 97.014651 | E36: =IFERROR(E32/E22,0) -> 163.9617 | F36: =IFERROR(F32/F22,0) -> 139.20733 | G36: =IFERROR(G32/G22,0) -> 140.66812 | H36: =IFERROR(H32/H22,0) -> 141.63829 | I36: =IFERROR(I32/I22,0) -> 132.79843 | ... M36: =IFERROR(M32/M22,0) -> 138.9944 | O36: =AVERAGE(B36:N36) -> 146.26511
A37: 👥 Costo de Personal por Hora Disponible (S/) | B37: =IFERROR(B33/B22,0) -> 150.4625 | C37: =IFERROR(C33/C22,0) -> 248.40822 | D37: =IFERROR(D33/D22,0) -> 100.96 | E37: =IFERROR(E33/E22,0) -> 134.37764 | F37: =IFERROR(F33/F22,0) -> 107.4384 | G37: =IFERROR(G33/G22,0) -> 120.66218 | H37: =IFERROR(H33/H22,0) -> 182.03124 | I37: =IFERROR(I33/I22,0) -> 143.5168 | ... M37: =IFERROR(M33/M22,0) -> 162.90784 | O37: =AVERAGE(B37:N37) -> 147.11383
A38: 💼 Costo Total por Hora Disponible (S/) | B38: =IFERROR(B34/B22,0) -> 559.11452 | C38: =IFERROR(C34/C22,0) -> 669.29978 | D38: =IFERROR(D34/D22,0) -> 389.56176 | E38: =IFERROR(E34/E22,0) -> 517.3717 | F38: =IFERROR(F34/F22,0) -> 459.88978 | G38: =IFERROR(G34/G22,0) -> 536.25119 | H38: =IFERROR(H34/H22,0) -> 557.98245 | I38: =IFERROR(I34/I22,0) -> 482.90199 | ... M38: =IFERROR(M34/M22,0) -> 529.01381 | O38: =AVERAGE(B38:N38) -> 521.24647
A39: 💰 Ingreso por Hora Disponible (S/) | B39: =IFERROR(B18/B22,0) -> 642.30397 | C39: =IFERROR(C18/C22,0) -> 789.59978 | D39: =IFERROR(D18/D22,0) -> 528.38618 | E39: =IFERROR(E18/E22,0) -> 563.87122 | F39: =IFERROR(F18/F22,0) -> 481.7863 | G39: =IFERROR(G18/G22,0) -> 513.72159 | H39: =IFERROR(H18/H22,0) -> 622.34483 | I39: =IFERROR(I18/I22,0) -> 581.00709 | ... M39: =IFERROR(M18/M22,0) -> 653.55928 | O39: =AVERAGE(B39:N39) -> 568.12653
A40: ★ MARGEN por Hora (S/) = Ingreso/hr − Costo/hr | B40: =B39-B38 -> 83.189449 | C40: =C39-C38 -> 120.3 | D40: =D39-D38 -> 138.82442 | E40: =E39-E38 -> 46.499514 | F40: =F39-F38 -> 21.896518 | G40: =G39-G38 -> -22.529603 | H40: =H39-H38 -> 64.362383 | I40: =I39-I38 -> 98.1051 | ... M40: =M39-M38 -> 124.54547 | O40: =AVERAGE(B40:N40) -> 46.880058
A41: Margen por Hora (%) | B41: =IFERROR(B40/B39,0) -> 0.12951726 | C41: =IFERROR(C40/C39,0) -> 0.15235567 | D41: =IFERROR(D40/D39,0) -> 0.26273287 | E41: =IFERROR(E40/E39,0) -> 0.082464777 | F41: =IFERROR(F40/F39,0) -> 0.04544861 | G41: =IFERROR(G40/G39,0) -> -0.043855667 | H41: =IFERROR(H40/H39,0) -> 0.10341916 | I41: =IFERROR(I40/I39,0) -> 0.16885353 | ... M41: =IFERROR(M40/M39,0) -> 0.19056492 | O41: =AVERAGE(B41:N41) -> 0.071443759
A43: 5. ANÁLISIS ENERGÉTICO — CHILLER 24/7 vs HORARIO PÚBLICO
A44: Horas Totales Chiller/mes (24hrs × días del mes) | B44: 744 | C44: 672 | D44: 744 | E44: 720 | F44: 744 | G44: 720 | H44: 744 | I44: 744 | J44: 720 | K44: 744 | L44: 720 | M44: 744 | O44: =SUM(B44:N44) -> 8760
A45: Energía Eléctrica Mensual (del P&L) | B45: ='P&L Gerencial'!C11 -> 22754.51 | C45: ='P&L Gerencial'!D11 -> 24839.76 | D45: ='P&L Gerencial'!E11 -> 23204.47 | E45: ='P&L Gerencial'!F11 -> 22781.98 | F45: ='P&L Gerencial'!G11 -> 20410.69 | G45: ='P&L Gerencial'!H11 -> 18773.92 | H45: ='P&L Gerencial'!I11 -> 17726.41 | I45: ='P&L Gerencial'!J11 -> 17115.76 | ... M45: ='P&L Gerencial'!N11 -> 18987.72 | O45: =SUM(B45:N45) -> 238552.34
A46: Costo Energía por Hora de Chiller (S/hr) | B46: =IFERROR(B45/B44,0) -> 30.584019 | C46: =IFERROR(C45/C44,0) -> 36.963929 | D46: =IFERROR(D45/D44,0) -> 31.188804 | E46: =IFERROR(E45/E44,0) -> 31.641639 | F46: =IFERROR(F45/F44,0) -> 27.433723 | G46: =IFERROR(G45/G44,0) -> 26.074889 | H46: =IFERROR(H45/H44,0) -> 23.82582 | I46: =IFERROR(I45/I44,0) -> 23.005054 | ... M46: =IFERROR(M45/M44,0) -> 25.521129 | O46: =AVERAGE(B46:N46) -> 27.303895
...

Sheet Punto de Equilibrio
A1: PERU ON ICE — ANÁLISIS DE PUNTO DE EQUILIBRIO (BREAK-EVEN)
A2: Todos los cálculos se actualizan automáticamente con los datos del P&L Gerencial e Indicadores Operativos
A4: 1. ESTRUCTURA DE COSTOS ANUAL 2025
A5: Ingresos Reales 2025 | B5: ='P&L Gerencial'!O6 -> 2002844 | C5: Fuente: P&L Gerencial
A6: Costos Operativos del Hielo (B) | B6: ='P&L Gerencial'!O24 -> 515452.91 | C6: Energía + Chiller + Operación directa
A7: Costo de Personal (C) | B7: ='P&L Gerencial'!O46 -> 517339.64 | C7: Planilla completa + cargas sociales
A8: Gastos Comerciales (D) | B8: ='P&L Gerencial'!O57 -> 105699.39 | C8: Marketing + comisiones
A9: Gastos Administrativos (E) | B9: ='P&L Gerencial'!O81 -> 75929.34 | C9: Asesorías + tributos + seguros
A10: Gastos de Estructura (F) | B10: ='P&L Gerencial'!O99 -> 622750.09 | C10: Alquiler local + servicios fijos
A12: 2. CLASIFICACIÓN: COSTOS FIJOS VS. VARIABLES
A13: (+) Costos Fijos Totales | B13: =B6+B7+B9+B10 -> 1731472 | C13: Op. Hielo + Personal + Adm. + Estructura
A14: (−) Costos Variables Totales | B14: =B8 -> 105699.39 | C14: Comercial: comisiones proporcionales a ventas
A15: % Costos Variables sobre Ventas | B15: =IFERROR(B14/B5,0) -> 0.052774651 | C15: Ratio para cálculo de punto de equilibrio
A16: Margen de Contribución (%) | B16: =1-B15 -> 0.94722535 | C16: % que queda de cada s/ de ingreso para cubrir costos fijos
A17: Margen de Contribución (S/) | B17: =IFERROR(B5*B16,0) -> 1897144.6 | C17: total disponible para cubrir costos fijos
A19: 3. PUNTO DE EQUILIBRIO — RESULTADOS
A20: ▶ Punto de equilibrio en VENTAS ANUALES (S/) | B20: =IFERROR(B13/B16,0) -> 1827940.9 | C20: ingresos mínimos anuales para cubrir todos los costos
A21: ▶ Punto de equilibrio MENSUAL Promedio (S/) | B21: =B20/12 -> 152328.41 | C21: ingresos mínimos por mes
A22: Punto de equilibrio como % de Ingresos Reales | B22: =IFERROR(B20/B5,0) -> 0.91267266 | C22: < 100% = negocio con margen positivo
A24: 4. PUNTO DE EQUILIBRIO EN HORAS Y OCUPACIÓN
A25: Ingreso Promedio por Hora Disponible (S/) | B25: =AVERAGE('Indicadores Operativos'!B39:N39) -> 568.12653 | C25: Revenue / Horas disponibles — NO confundir con ticket/persona (S/41.5)
A26: Horas Disponibles Anuales | B26: ='Indicadores Operativos'!O22 -> 3534.3 | C26: Del Driver Operativo
A27: ▶ Punto de equilibrio en HORAS DE USO ANUALES | B27: =IFERROR(B20/B25,0) -> 3217.4891 | C27: horas de pista necesarias público recreativo para punto de equilibrio
A28: ▶ Punto de equilibrio en % OCUPACIÓN | B28: =IFERROR(B27/B26,0) -> 0.91036107 | C28: % ocupación mínimo para cubrir todos los costos
A29: Ocupación Real 2025 (estimada) | B29: =AVERAGE('Indicadores Operativos'!B27:N27) -> 0.18704204 | C29: Promedio anual ocupación real estimada
A30: GAP Ocupación (Real − Punto de equilibrio) | B30: =B29-B28 -> -0.72331903 | C30: Positivo = margen de seguridad sobre el break-even
A32: 5. ANÁLISIS DE SENSIBILIDAD — IMPACTO DE CAMBIOS EN PRECIO Y OCUPACIÓN
A33: Variación del BE ante cambios en precio promedio/hora:
A34: Precio -20% | B34: =IFERROR((B13/(1-B15))/(B25*(1+-0.2))/B26,0) -> 1.1379513 | C34: ocupación mínima para BE
A35: Precio -10% | B35: =IFERROR((B13/(1-B15))/(B25*(1+-0.1))/B26,0) -> 1.0115123 | C35: ocupación mínima para BE
A36: Precio +0% | B36: =IFERROR((B13/(1-B15))/(B25*(1+0))/B26,0) -> 0.91036107 | C36: ocupación mínima para BE
A37: Precio +10% | B37: =IFERROR((B13/(1-B15))/(B25*(1+0.1))/B26,0) -> 0.82760097 | C37: ocupación mínima para BE
A38: Precio +20% | B38: =IFERROR((B13/(1-B15))/(B25*(1+0.2))/B26,0) -> 0.75863422 | C38: ocupación mínima para BE
A40: 6. PUNTO DE EQUILIBRIO POR PERSONA — ANÁLISIS DE TARIFAS (PRECIOS NETOS SIN IGV)
A41: PRODUCTO / TARIFA | B41: PRECIO NETO S/IGV (S/) | C41: COSTO VAR. POR PERSONA | D41: CONTRIBUCIÓN / PERSONA (S/) | E41: PERSONAS BE / AÑO | F41: PERSONAS BE / MES | G41: PERSONAS BE/DÍA (30 días/mes)
A42: Entrada 25 minutos | B42: =Simulador!D6 -> 33.9 | C42: =B42*B15 -> 1.7890607 | D42: =B42-C42 -> 32.110939 | E42: =IFERROR(ROUND(B13/D42,0),0) -> 53922 | F42: =IFERROR(ROUND(E42/12,0),0) -> 4494 | G42: =IFERROR(ROUND(F42/30,0),0) -> 150
A43: Entrada 55 minutos | B43: =Simulador!D7 -> 59.32 | C43: =B43*B15 -> 3.1305923 | D43: =B43-C43 -> 56.189408 | E43: =IFERROR(ROUND(B13/D43,0),0) -> 30815 | F43: =IFERROR(ROUND(E43/12,0),0) -> 2568 | G43: =IFERROR(ROUND(F43/30,0),0) -> 86
A44: Membresía Coach/mes | B44: =Simulador!D8 -> 186.44 | C44: =B44*B15 -> 9.8393058 | D44: =B44-C44 -> 176.60069 | E44: =IFERROR(ROUND(B13/D44,0),0) -> 9804 | F44: =IFERROR(ROUND(E44/12,0),0) -> 817 | G44: =IFERROR(ROUND(F44/30,0),0) -> 27
A45: Membresía Deportistas/mes | B45: =Simulador!D9 -> 296.61 | C45: =B45*B15 -> 15.653489 | D45: =B45-C45 -> 280.95651 | E45: =IFERROR(ROUND(B13/D45,0),0) -> 6163 | F45: =IFERROR(ROUND(E45/12,0),0) -> 514 | G45: =IFERROR(ROUND(F45/30,0),0) -> 17
A46: Salón Off-Ice | B46: =Simulador!D10 -> 50.85 | C46: =B46*B15 -> 2.683591 | D46: =B46-C46 -> 48.166409 | E46: =IFERROR(ROUND(B13/D46,0),0) -> 35948 | F46: =IFERROR(ROUND(E46/12,0),0) -> 2996 | G46: =IFERROR(ROUND(F46/30,0),0) -> 100
...

Sheet Estrategia de Precios
A1: PERU ON ICE S.A.C. — ESTRATEGIA DE PRECIOS Y HOJA DE RUTA HACIA EL 30% DE MARGEN EBITDA
A2: Diagnóstico 2025 | Propuesta tarifaria 2026 | Palancas de mejora | Metas por línea del P&L | Moneda: S/ sin IGV
A4: MARGEN EBITDA 2025 | C4: EBITDA 2025 (S/) | E4: GAP A CERRAR | G4: VISITAS/DÍA 2025 | I4: OCUP. ACTUAL
A5: 0.082718671 | C5: 165672.59 | E5: 672378.79 | G5: 132.18904 | I5: 0.187
A6: Actual — objetivo: 30% | C6: vs target S/600,853 | E6: Revenue adicional necesario | G6: Target: 180+ visitas/día | I6: Target: 35%+ en horario pico
A8: ▌ BLOQUE 1 — NUEVA ESTRUCTURA DE TARIFAS PROPUESTAS
A9: CATEGORÍA | B9: SERVICIO / DESCRIPCIÓN | C9: MIN | D9: PRECIO c/IGV | E9: IGV (18%) | F9: PRECIO NETO s/IGV | G9: PRECIO ANT. s/IGV | H9: VARIACIÓN | I9: MEMBRESÍA c/IGV | J9: MBR NETO s/IGV | K9: TIPO / OBSERVACIÓN
A10: PÚBLICO GENERAL | B10: Entrada estándar | C10: 25 | D10: 40 | E10: 6.1 | F10: 33.9 | G10: 29.66 | H10: 0.14291429 | I10: — | J10: — | K10: Tarifa principal — turno 25 min en pista
A11: PÚBLICO GENERAL | B11: Entrada extendida | C11: 55 | D11: 65 | E11: 9.92 | F11: 55.08 | G11: 50.85 | H11: 0.08324 | I11: — | J11: — | K11: Turno 55 min en pista
A12: PÚBLICO GENERAL | B12: Full Day | C12: — | D12: 150 | E12: 22.88 | F12: 127.12 | G12: — | H12: 🆕 NUEVO | I12: — | J12: — | K12: Acceso todo el día (horario público)
A13: FREE PRACTICE | B13: 5AM – 9AM | C13: 60 | D13: 40 | E13: 6.1 | F13: 33.9 | G13: — | H13: 🆕 NUEVO | I13: — | J13: — | K13: Entrenamiento libre madrugada, 1 hr
A14: CLUBES | B14: Solo horario de clases | C14: — | D14: — | E14: — | F14: — | G14: — | H14: — | I14: 350 | J14: 296.61 | K14: Membresía mensual
A15: OFF ICE – CLUBES | B15: Horario de clases x hora | C15: 60 | D15: 60 | E15: 9.15 | F15: 50.85 | G15: — | H15: 🆕 NUEVO | I15: — | J15: — | K15: Uso salón Off-Ice durante clases
A16: COACHES | B16: Clases particulares x hora | C16: 60 | D16: 30 | E16: 4.58 | F16: 25.42 | G16: 25.42 | H16: — | I16: 250 | J16: 211.86 | K16: Membresía mensual
A17: SOLO ENTRENAMIENTO | B17: Coach 5AM – 9AM | C17: — | D17: 20 | E17: 3.05 | F17: 16.95 | G17: — | H17: 🆕 NUEVO | I17: 200 | J17: 169.49 | K17: Membresía mensual
A18: OFF ICE | B18: Clase x hora | C18: 60 | D18: 80 | E18: 12.2 | F18: 67.8 | G18: — | H18: 🆕 NUEVO | I18: — | J18: — | K18: Salón Off-Ice sin pista
A19: PACKS CLASES | B19: Pack 600 min particulares | C19: 600 | D19: 300 | E19: 45.76 | F19: 254.24 | G19: — | H19: 🆕 NUEVO | I19: — | J19: — | K19: 10 hrs de clases particulares
A20: PACKS CLASES | B20: Pack 1200 min particulares | C20: 1200 | D20: 450 | E20: 68.64 | F20: 381.36 | G20: — | H20: 🆕 NUEVO | I20: — | J20: — | K20: 20 hrs de clases particulares — mayor volumen
A21: CLASES CLUB POI | B21: Pack 240 min | C21: 240 | D21: 380 | E21: 57.97 | F21: 322.03 | G21: — | H21: 🆕 NUEVO | I21: — | J21: — | K21: 4 hrs clases Club POI
A22: CLASES CLUB POI | B22: Pack 480 min | C22: 480 | D22: 760 | E22: 115.93 | F22: 644.07 | G22: — | H22: 🆕 NUEVO | I22: — | J22: — | K22: 8 hrs clases Club POI
A23: SOCIAL | B23: CONADIS | C23: — | D23: GRATIS | E23: — | F23: — | G23: — | H23: — | I23: — | K23: Acceso gratuito — responsabilidad social
A24: SOCIAL | B24: Cumpleañero acompañado | C24: — | D24: GRATIS | E24: — | F24: — | G24: — | H24: — | I24: — | K24: Gratuito si viene con grupo — genera visitas pagadas
A26: ▌ BLOQUE 2 — SIMULACIÓN DE INGRESOS MENSUALES CON NUEVAS TARIFAS
A27: CATEGORÍA | B27: SERVICIO | C27: PRECIO NETO (S/) | D27: VOLUMEN/MES (editable) | E27: INGRESO/MES (S/) | F27: INGRESO/AÑO (S/) | G27: % DEL TOTAL | H27: CV (5.3%) | I27: CONTRIBUCIÓN/MES | K27: NOTA
A28: PÚBLICO GENERAL | B28: Entrada estándar | C28: 33.9 | D28: 3200 | E28: =C28*D28 -> 108480 | F28: =E28*12 -> 1301760 | G28: =IFERROR(E28/E43,0) -> 0.51459734 | H28: =E28*0.0528 -> 5727.744 | I28: =E28-H28 -> 102752.26 | K28: Base: -15% volumen vs 2025, +14% precio → mayor ticket unitario
A29: PÚBLICO GENERAL | B29: Entrada extendida | C29: 55.08 | D29: 1100 | E29: =C29*D29 -> 60588 | F29: =E29*12 -> 727056 | G29: =IFERROR(E29/E43,0) -> 0.28741172 | H29: =E29*0.0528 -> 3199.0464 | I29: =E29-H29 -> 57388.954 | K29: Base conservadora ajustada
A30: PÚBLICO GENERAL | B30: Full Day | C30: 127.12 | D30: 10 | E30: =C30*D30 -> 1271.2 | F30: =E30*12 -> 15254.4 | G30: =IFERROR(E30/E43,0) -> 0.0060302003 | H30: =E30*0.0528 -> 67.11936 | I30: =E30-H30 -> 1204.0806 | K30: Nuevo producto — alta elasticidad en temporada alta
A31: FREE PRACTICE | B31: 5AM – 9AM | C31: 33.9 | D31: 90 | E31: =C31*D31 -> 3051 | F31: =E31*12 -> 36612 | G31: =IFERROR(E31/E43,0) -> 0.01447305 | H31: =E31*0.0528 -> 161.0928 | I31: =E31-H31 -> 2889.9072 | K31: Nuevo segmento: atletas y entusiastas tempranos
A32: CLUBES | B32: Solo horario de clases | C32: 296.61 | D32: 70 | E32: =C32*D32 -> 20762.7 | F32: =E32*12 -> 249152.4 | G32: =IFERROR(E32/E43,0) -> 0.098492165 | H32: =E32*0.0528 -> 1096.2706 | I32: =E32-H32 -> 19666.429 | K32: Membresía actual mantenida — base de ingresos recurrentes
A33: OFF ICE – CLUBES | B33: Horario de clases x hora | C33: 50.85 | D33: 60 | E33: =C33*D33 -> 3051 | F33: =E33*12 -> 36612 | G33: =IFERROR(E33/E43,0) -> 0.01447305 | H33: =E33*0.0528 -> 161.0928 | I33: =E33-H33 -> 2889.9072 | K33: Nuevo: monetiza el espacio fuera del hielo
A34: COACHES | B34: Clases particulares x hora | C34: 25.42 | D34: 10 | E34: =C34*D34 -> 254.2 | F34: =E34*12 -> 3050.4 | G34: =IFERROR(E34/E43,0) -> 0.0012058503 | H34: =E34*0.0528 -> 13.42176 | I34: =E34-H34 -> 240.77824 | K34: Nuevo: clases privadas son el mayor margen por hora
A35: SOLO ENTRENAMIENTO | B35: Coach 5AM – 9AM | C35: 16.95 | D35: 10 | E35: =C35*D35 -> 169.5 | F35: =E35*12 -> 2034 | G35: =IFERROR(E35/E43,0) -> 0.00080405834 | H35: =E35*0.0528 -> 8.9496 | I35: =E35-H35 -> 160.5504 | K35: Nuevo: acceso premium madrugada
A36: OFF ICE | B36: Clase x hora | C36: 67.8 | D36: 10 | E36: =C36*D36 -> 678 | F36: =E36*12 -> 8136 | G36: =IFERROR(E36/E43,0) -> 0.0032162333 | H36: =E36*0.0528 -> 35.7984 | I36: =E36-H36 -> 642.2016 | K36: Nuevo: Off-Ice sin pista = costo marginal casi cero
A37: PACKS CLASES | B37: Pack 600 min particulares | C37: 254.24 | D37: 10 | E37: =C37*D37 -> 2542.4 | F37: =E37*12 -> 30508.8 | G37: =IFERROR(E37/E43,0) -> 0.012060401 | H37: =E37*0.0528 -> 134.23872 | I37: =E37-H37 -> 2408.1613 | K37: Nuevo: pack de horas — genera ingreso anticipado
A38: PACKS CLASES | B38: Pack 1200 min particulares | C38: 381.36 | D38: 5 | E38: =C38*D38 -> 1906.8 | F38: =E38*12 -> 22881.6 | G38: =IFERROR(E38/E43,0) -> 0.0090453005 | H38: =E38*0.0528 -> 100.67904 | I38: =E38-H38 -> 1806.121 | K38: Nuevo: máximo descuento por volumen alto
A39: CLASES CLUB POI | B39: Pack 240 min | C39: 322.03 | D39: 15 | E39: =C39*D39 -> 4830.45 | F39: =E39*12 -> 57965.4 | G39: =IFERROR(E39/E43,0) -> 0.022914239 | H39: =E39*0.0528 -> 255.04776 | I39: =E39-H39 -> 4575.4022 | K39: Nuevo: Club POI — base de fans
A40: CLASES CLUB POI | B40: Pack 480 min | C40: 644.07 | D40: 5 | E40: =C40*D40 -> 3220.35 | F40: =E40*12 -> 38644.2 | G40: =IFERROR(E40/E43,0) -> 0.015276397 | H40: =E40*0.0528 -> 170.03448 | I40: =E40-H40 -> 3050.3155 | K40: Nuevo: pack POI — compromiso largo plazo
A41: SOCIAL | B41: CONADIS | C41: — | D41: 0 | E41: GRATIS | F41: — | G41: — | H41: — | I41: — | K41: Responsabilidad social — sin impacto en margen
A42: SOCIAL | B42: Cumpleañero acompañado | C42: — | D42: 0 | E42: GRATIS | F42: — | G42: — | H42: — | I42: — | K42: Generador de visitas pagadas del grupo acompañante
A43: TOTAL INGRESOS / MES | E43: =E28+E29+E30+E31+E32+E33+E34+E35+E36+E37+E38+E39+E40 -> 210805.6 | F43: =F28+F29+F30+F31+F32+F33+F34+F35+F36+F37+F38+F39+F40 -> 2529667.2 | H43: =E43*0.0528 -> 11130.536 | I43: =E43-H43 -> 199675.06
...

Sheet Simulador
A1: PERU ON ICE — SIMULADOR DE INGRESOS POR TARIFAS Y MIX DE PRODUCTOS
A4: 📋 BLOQUE 1: TARIFAS VIGENTES — PRECIOS POR PRODUCTO
A5: PRODUCTO / SERVICIO | B5: PRECIO CON IGV (S/) | C5: IGV (S/) | D5: PRECIO NETO SIN IGV (S/) | E5: DESCRIPCIÓN
A6: Entrada 25 minutos | B6: 40 | C6: =ROUND(B6*$B$13/(1+$B$13),2) -> 6.1 | D6: =ROUND(B6/(1+$B$13),2) -> 33.9
A7: Entrada 55 minutos | B7: 70 | C7: =ROUND(B7*$B$13/(1+$B$13),2) -> 10.68 | D7: =ROUND(B7/(1+$B$13),2) -> 59.32
A8: Membresía Coach | B8: 220 | C8: =ROUND(B8*$B$13/(1+$B$13),2) -> 33.56 | D8: =ROUND(B8/(1+$B$13),2) -> 186.44
A9: Membresía Deportistas | B9: 350 | C9: =ROUND(B9*$B$13/(1+$B$13),2) -> 53.39 | D9: =ROUND(B9/(1+$B$13),2) -> 296.61
A10: Salón Off-Ice | B10: 60 | C10: =ROUND(B10*$B$13/(1+$B$13),2) -> 9.15 | D10: =ROUND(B10/(1+$B$13),2) -> 50.85
A11: 🆕 Nuevo Producto 1 | B11: 0 | C11: =ROUND(B11*$B$13/(1+$B$13),2) -> 0 | D11: =ROUND(B11/(1+$B$13),2) -> 0
A12: 🆕 Nuevo Producto 2 | B12: 0 | C12: =ROUND(B12*$B$13/(1+$B$13),2) -> 0 | D12: =ROUND(B12/(1+$B$13),2) -> 0
A13: ⚙ TASA IGV | B13: 0.18 | C13: ← IGV 18% incluido en el precio al cliente
A14: 📊 BLOQUE 2: VOLUMEN MENSUAL (MES PROMEDIO)
A15: PRODUCTO | B15: CANTIDAD/MES (editable) | C15: PRECIO NETO SIN IGV (S/) | D15: INGRESOS /MES (S/) | E15: INGRESOS/AÑO | F15: % DEL TOTAL | G15: NOTA
A16: Entrada 25 minutos | B16: 3820 | C16: =D6 -> 33.9 | D16: =B16*C16 -> 129498 | E16: =D16*12 -> 1553976 | F16: =IFERROR(D16/D23,0) -> 0.58638093 | G16: Calibrado de Feb 2025: 74% × 5,162 visitas → S/133,700
A17: Entrada 55 minutos | B17: 1342 | C17: =D7 -> 59.32 | D17: =B17*C17 -> 79607.44 | E17: =D17*12 -> 955289.28 | F17: =IFERROR(D17/D23,0) -> 0.36047108 | G17: Calibrado de Feb 2025: 26% × 5,162 visitas → S/80,520
A18: Membresía Coach | B18: 15 | C18: =D8 -> 186.44 | D18: =B18*C18 -> 2796.6 | E18: =D18*12 -> 33559.2 | F18: =IFERROR(D18/D23,0) -> 0.012663307 | G18: Estimado — actualizar con datos reales
A19: Membresía Deportistas | B19: 25 | C19: =D9 -> 296.61 | D19: =B19*C19 -> 7415.25 | E19: =D19*12 -> 88983 | F19: =IFERROR(D19/D23,0) -> 0.033577053 | G19: Estimado — actualizar con datos reales
A20: Salón Off-Ice | B20: 30 | C20: =D10 -> 50.85 | D20: =B20*C20 -> 1525.5 | E20: =D20*12 -> 18306 | F20: =IFERROR(D20/D23,0) -> 0.0069076287 | G20: Estimado — actualizar con datos reales
A21: 🆕 Nuevo Producto 1 | B21: 0 | C21: =D11 -> 0 | D21: =B21*C21 -> 0 | E21: =D21*12 -> 0 | F21: =IFERROR(D21/D23,0) -> 0 | G21: Nuevo producto — ingresa cantidad
A22: 🆕 Nuevo Producto 2 | B22: 0 | C22: =D12 -> 0 | D22: =B22*C22 -> 0 | E22: =D22*12 -> 0 | F22: =IFERROR(D22/D23,0) -> 0 | G22: Nuevo producto — ingresa cantidad
A23: TOTAL INGRESOS / MES | D23: =D16+D17+D18+D19+D20+D21+D22 -> 220842.79 | E23: =D23*12 -> 2650113.5 | F23: 100%
A24: Ticket Promedio Ponderado (S/) | D24: =IFERROR(D23/SUM(B16:B20),0) -> 42.210013
A26: 💰 BLOQUE 3: COSTOS Y EBITDA SIMULADO
A27: CONCEPTO | B27: MENSUAL (S/) | C27: ANUAL (S/) | D27: % INGRESOS | F27: EDITABLE | G27: FUENTE
A28: ( - ) Costos Variables (% ingresos) | B28: 0.0528 | C28: % ingresos | D28: Comis. tarjeta+ventas+marketing. Del P&L 2025.
A29: → Costos Variables S/ | B29: =ROUND(D23*B28,0) -> 11660 | C29: =B29*12 -> 139920 | D29: =IFERROR(B29/D23,0) -> 0.052797739
A30: Margen de Contribución | B30: =D23-B29 -> 209182.79 | C30: =B30*12 -> 2510193.5 | D30: =IFERROR(B30/D23,0) -> 0.94720226
A32: ( - ) Costos Op. Hielo / mes | B32: 42954 | C32: S/ | D32: Del P&L 2025 anual / 12 meses
A33: ( - ) Personal / mes | B33: 43112 | C33: S/ | D33: Del P&L 2025 anual / 12 meses
A34: ( - ) Administrativo / mes | B34: 6327 | C34: S/ | D34: Del P&L 2025 anual / 12 meses
A35: ( - ) Estructura (Alquiler+Servicios) / mes | B35: 51896 | C35: S/ | D35: Del P&L 2025 anual / 12 meses
A36: Total Costos Fijos / mes | B36: =B32+B33+B34+B35 -> 144289 | C36: =B36*12 -> 1731468 | D36: =IFERROR(B36/D23,0) -> 0.65335617
A38: ★★ EBITDA MENSUAL SIMULADO | B38: =B30-B36 -> 64893.79 | C38: =B38*12 -> 778725.48 | D38: =IFERROR(B38/D23,0) -> 0.29384609
A40: 📈 BLOQUE 4: COMPARATIVO vs REAL 2025
A41: MÉTRICA | B41: SIMULADO | C41: BASE 2025 (mensual prom.) | D41: DIFERENCIA (S/) | E41: MEJORA (%)
A42: Ingresos Mensuales (S/) | B42: =D23 -> 220842.79 | C42: 166904 | D42: =B42-C42 -> 53938.79 | E42: =IFERROR((B42-C42)/ABS(C42),0) -> 0.32317254
A43: EBITDA Mensual (S/) | B43: =B38 -> 64893.79 | C43: 13806 | D43: =B43-C43 -> 51087.79 | E43: =IFERROR((B43-C43)/ABS(C43),0) -> 3.7004049
A44: EBITDA Anual (S/) | B44: =C38 -> 778725.48 | C44: 165673 | D44: =B44-C44 -> 613052.48 | E44: =IFERROR((B44-C44)/ABS(C44),0) -> 3.7003765
A45: Margen EBITDA (%) | B45: =D38 -> 0.29384609 | C45: 0.0827 | D45: =B45-C45 -> 0.21114609 | E45: =IFERROR((B45-C45)/ABS(C45),0) -> 2.5531571
A46: Punto de quilibrio Mensual (S/) | B46: =IFERROR(B36/(1-B28),0) -> 152332.14 | C46: 152328 | D46: =B46-C46 -> 4.1368243 | E46: =IFERROR((B46-C46)/ABS(C46),0) -> 2.7157347e-05
...

Sheet Datos 2026
A1: PERU ON ICE — BASE DE DATOS P&L 2026 (PRESUPUESTO ENE-DIC)
A2: Fuente: P&L 2026 original + proyección +7% sobre 2025
A3: CUENTA | B3: DESCRIPCIÓN | C3: ENE | D3: FEB | E3: MAR | F3: ABR | G3: MAY | H3: JUN | I3: JUL | J3: AGO | K3: SET | L3: OCT | M3: NOV | N3: DIC | O3: TOTAL | P3: % REV.
A4: 7032100 | B4: Servicios-Local-Terceros | C4: 192370.04 | D4: 214297.38 | E4: 170177.34 | F4: 173762.55 | G4: 156921.65 | H4: 159132.97 | I4: 198440.87 | J4: 190171.17 | K4: 149187.06 | L4: 154118.53 | M4: 149910.55 | N4: 206086.19 | O4: =SUM(C4:N4) -> 2114576.3 | P4: =IFERROR(O4/O4,0) -> 1
A5: 7761100 | B5: Diferencia en cambio | C5: 0.69 | D5: 0.94 | E5: 0 | F5: 5.08 | G5: 2.4 | H5: 174.7 | I5: 157.27 | J5: 82.85 | K5: 120.88 | L5: 196.28 | M5: 24.43 | N5: 598.71 | O5: =SUM(C5:N5) -> 1364.23 | P5: =IFERROR(O5/O4,0) -> 0.00064515525
A6: 7761101 | B6: Diferencia de Redondeo | C6: 10.66 | D6: 0.01 | E6: 0.15 | F6: 9.07 | G6: 1.18 | H6: 0.77 | I6: 0 | J6: 10.01 | K6: 0.01 | L6: 0 | M6: 0.03 | N6: 0.06 | O6: =SUM(C6:N6) -> 31.95 | P6: =IFERROR(O6/O4,0) -> 1.510941e-05
A7: 6211100 | B7: Sueldos y salarios | C7: 28638 | D7: 24200 | E7: 26007.68 | F7: 25053 | G7: 24486 | H7: 25517.98 | I7: 25702.6 | J7: 23177 | K7: 23862.54 | L7: 23877 | M7: 21864.5 | N7: 19113.51 | O7: =SUM(C7:N7) -> 291499.81 | P7: =IFERROR(O7/O4,0) -> 0.13785259
